Workbook
Name Slicer_Age_Group: #N/A
Name Slicer_Months__Sale_Date: #N/A
Name Slicer_Product_Category: #N/A
Name Slicer_State: #N/A

Sheet Cleaned data
A1: Order_ID | B1: Product_ID | C1: Sale_Date | D1: Month | E1: Customer_Name | F1: Age | G1: City | H1: State | I1: Region | J1: Quantity_Sold | K1: Product_Category | L1: Unit_Cost | M1: Unit_Price | N1: Customer_Type | O1: Discount | P1: Payment_Method | Q1: Sales_Channel | R1: Order_Status | S1: Sales_Amount | T1: Cost_Price | U1: Profit | V1: Age_Group
A2: ORD1000 | B2: 1052 | C2: 44960 | D2: =TEXT(C2,"mmm") -> Feb | E2: Suman Mukherjee | F2: 55 | G2: Bangalore | H2: Karnataka | I2: East | J2: 18 | K2: Furniture | L2: 152.75 | M2: 267.22 | N2: Returning | O2: 0.09 | P2: Cash | Q2: Offline | R2: Delivered | S2: =J2*M2*(1-O2) -> 4377.0636 | T2: =L2*J2 -> 2749.5 | U2: =S2-T2 -> 1627.5636 | V2: =_xlfn.IFS( F2<25,"Young", F2<=40,"Adult", F2>40,"Senior" ) -> Senior
A3: ORD1001 | B3: 1093 | C3: 45037 | D3: =TEXT(C3,"mmm") -> Apr | E3: Kavita Mukherjee | F3: 50 | G3: Chennai | H3: Tamil Nadu | I3: West | J3: 17 | K3: Furniture | L3: 3816.39 | M3: 4209.44 | N3: Returning | O3: 0.1 | P3: Cash | Q3: Online | R3: Cancelled | S3: =J3*M3*(1-O3) -> 64404.432 | T3: =L3*J3 -> 64878.63 | U3: =S3-T3 -> -474.198 | V3: =_xlfn.IFS( F3<25,"Young", F3<=40,"Adult", F3>40,"Senior" ) -> Senior
A4: ORD1002 | B4: 1015 | C4: 45190 | D4: =TEXT(C4,"mmm") -> Sep | E4: Pooja Iyer | F4: 41 | G4: Bangalore | H4: Maharashtra | I4: East | J4: 30 | K4: Food | L4: 261.56 | M4: 371.4 | N4: Returning | O4: 0.2 | P4: Bank Transfer | Q4: Online | R4: Returned | S4: =J4*M4*(1-O4) -> 8913.6 | T4: =L4*J4 -> 7846.8 | U4: =S4-T4 -> 1066.8 | V4: =_xlfn.IFS( F4<25,"Young", F4<=40,"Adult", F4>40,"Senior" ) -> Senior
A5: ORD1003 | B5: 1072 | C5: 45162 | D5: =TEXT(C5,"mmm") -> Aug | E5: Neha Mukherjee | F5: 32 | G5: Chennai | H5: Tamil Nadu | I5: North | J5: 39 | K5: Clothing | L5: 4330.03 | M5: 4467.75 | N5: New | O5: 0.02 | P5: Credit Card | Q5: Online | R5: Delivered | S5: =J5*M5*(1-O5) -> 170757.4 | T5: =L5*J5 -> 168871.17 | U5: =S5-T5 -> 1886.235 | V5: =_xlfn.IFS( F5<25,"Young", F5<=40,"Adult", F5>40,"Senior" ) -> Adult
A6: ORD1004 | B6: 1061 | C6: 45009 | D6: =TEXT(C6,"mmm") -> Mar | E6: Rohit Gupta | F6: 47 | G6: Chennai | H6: Tamil Nadu | I6: South | J6: 13 | K6: Electronics | L6: 637.37 | M6: 692.71 | N6: New | O6: 0.08 | P6: Credit Card | Q6: Online | R6: Returned | S6: =J6*M6*(1-O6) -> 8284.8116 | T6: =L6*J6 -> 8285.81 | U6: =S6-T6 -> -0.9984 | V6: =_xlfn.IFS( F6<25,"Young", F6<=40,"Adult", F6>40,"Senior" ) -> Senior
A7: ORD1005 | B7: 1021 | C7: 44968 | D7: =TEXT(C7,"mmm") -> Feb | E7: Abhishek Ghosh | F7: 59 | G7: Chennai | H7: Delhi | I7: North | J7: 32 | K7: Food | L7: 900.79 | M7: 1106.51 | N7: New | O7: 0.21 | P7: Cash | Q7: Online | R7: Returned | S7: =J7*M7*(1-O7) -> 27972.573 | T7: =L7*J7 -> 28825.28 | U7: =S7-T7 -> -852.7072 | V7: =_xlfn.IFS( F7<25,"Young", F7<=40,"Adult", F7>40,"Senior" ) -> Senior
A8: ORD1006 | B8: 1083 | C8: 45027 | D8: =TEXT(C8,"mmm") -> Apr | E8: Sneha Das | F8: 34 | G8: Bangalore | H8: Maharashtra | I8: South | J8: 29 | K8: Furniture | L8: 2408.81 | M8: 2824.09 | N8: Returning | O8: 0.04 | P8: Cash | Q8: Offline | R8: Cancelled | S8: =J8*M8*(1-O8) -> 78622.666 | T8: =L8*J8 -> 69855.49 | U8: =S8-T8 -> 8767.1756 | V8: =_xlfn.IFS( F8<25,"Young", F8<=40,"Adult", F8>40,"Senior" ) -> Adult
A9: ORD1007 | B9: 1087 | C9: 44932 | D9: =TEXT(C9,"mmm") -> Jan | E9: Amit Malhotra | F9: 22 | G9: Bangalore | H9: Maharashtra | I9: East | J9: 46 | K9: Furniture | L9: 3702.51 | M9: 3964.65 | N9: New | O9: 0.12 | P9: Bank Transfer | Q9: Offline | R9: Returned | S9: =J9*M9*(1-O9) -> 160489.03 | T9: =L9*J9 -> 170315.46 | U9: =S9-T9 -> -9826.428 | V9: =_xlfn.IFS( F9<25,"Young", F9<=40,"Adult", F9>40,"Senior" ) -> Young
A10: ORD1008 | B10: 1075 | C10: 45106 | D10: =TEXT(C10,"mmm") -> Jun | E10: Suman Das | F10: 46 | G10: Chennai | H10: Maharashtra | I10: North | J10: 30 | K10: Furniture | L10: 738.06 | M10: 1095.45 | N10: New | O10: 0.05 | P10: Bank Transfer | Q10: Offline | R10: Cancelled | S10: =J10*M10*(1-O10) -> 31220.325 | T10: =L10*J10 -> 22141.8 | U10: =S10-T10 -> 9078.525 | V10: =_xlfn.IFS( F10<25,"Young", F10<=40,"Adult", F10>40,"Senior" ) -> Senior
A11: ORD1009 | B11: 1075 | C11: 45208 | D11: =TEXT(C11,"mmm") -> Oct | E11: Kavita Ghosh | F11: 21 | G11: Delhi | H11: Tamil Nadu | I11: East | J11: 18 | K11: Clothing | L11: 2228.35 | M11: 2682.34 | N11: New | O11: 0.13 | P11: Bank Transfer | Q11: Offline | R11: Delivered | S11: =J11*M11*(1-O11) -> 42005.444 | T11: =L11*J11 -> 40110.3 | U11: =S11-T11 -> 1895.1444 | V11: =_xlfn.IFS( F11<25,"Young", F11<=40,"Adult", F11>40,"Senior" ) -> Young
A12: ORD1010 | B12: 1088 | C12: 45246 | D12: =TEXT(C12,"mmm") -> Nov | E12: Sourav Gupta | F12: 27 | G12: Mumbai | H12: Karnataka | I12: South | J12: 13 | K12: Furniture | L12: 2440.11 | M12: 2517.6 | N12: New | O12: 0.12 | P12: Bank Transfer | Q12: Online | R12: Returned | S12: =J12*M12*(1-O12) -> 28801.344 | T12: =L12*J12 -> 31721.43 | U12: =S12-T12 -> -2920.086 | V12: =_xlfn.IFS( F12<25,"Young", F12<=40,"Adult", F12>40,"Senior" ) -> Adult
A13: ORD1011 | B13: 1100 | C13: 45152 | D13: =TEXT(C13,"mmm") -> Aug | E13: Arjun Chatterjee | F13: 34 | G13: Mumbai | H13: Maharashtra | I13: West | J13: 43 | K13: Food | L13: 1100.81 | M13: 1137.44 | N13: Returning | O13: 0.08 | P13: Bank Transfer | Q13: Online | R13: Delivered | S13: =J13*M13*(1-O13) -> 44997.126 | T13: =L13*J13 -> 47334.83 | U13: =S13-T13 -> -2337.7036 | V13: =_xlfn.IFS( F13<25,"Young", F13<=40,"Adult", F13>40,"Senior" ) -> Adult
... A301: ORD1299 | B301: 1048 | C301: 44945 | D301: =TEXT(C301,"mmm") -> Jan | E301: Arjun Iyer | F301: 30 | G301: Chennai | H301: West Bengal | I301: West | J301: 7 | K301: Clothing | L301: 4310.95 | M301: 4723.2 | N301: Returning | O301: 0.05 | P301: Credit Card | Q301: Offline | R301: Delivered | S301: =J301*M301*(1-O301) -> 31409.28 | T301: =L301*J301 -> 30176.65 | U301: =S301-T301 -> 1232.63 | V301: =_xlfn.IFS( F301<25,"Young", F301<=40,"Adult", F301>40,"Senior" ) -> Adult

Sheet sales_data
A1: Order_ID | B1: Product_ID | C1: Sale_Date | D1: Customer_Name | E1: Age | F1: City | G1: State | H1: Region | I1: Quantity_Sold | J1: Product_Category | K1: Unit_Cost | L1: Unit_Price | M1: Customer_Type | N1: Discount | O1: Payment_Method | P1: Sales_Channel | Q1: Order_Status
A2: ORD1000 | B2: 1052 | C2: 44960 | D2: Suman Mukherjee | E2: 55 | F2: Bangalore | G2: Karnataka | H2: East | I2: 18 | J2: Furniture | K2: 152.75 | L2: 267.22 | M2: Returning | N2: 0.09 | O2: Cash | P2: Offline | Q2: Delivered
A3: ORD1001 | B3: 1093 | C3: 45037 | D3: Kavita Mukherjee | E3: 50 | F3: Chennai | G3: Tamil Nadu | H3: West | I3: 17 | J3: Furniture | K3: 3816.39 | L3: 4209.44 | M3: Returning | N3: 0.1 | O3: Cash | P3: Online | Q3: Cancelled
A4: ORD1002 | B4: 1015 | C4: 45190 | D4: Pooja Iyer | E4: 41 | F4: Bangalore | G4: Maharashtra | H4: East | I4: 30 | J4: Food | K4: 261.56 | L4: 371.4 | M4: Returning | N4: 0.2 | O4: Bank Transfer | P4: Online | Q4: Returned
A5: ORD1003 | B5: 1072 | C5: 45162 | D5: Neha Mukherjee | E5: 32 | F5: Chennai | G5: Tamil Nadu | H5: North | I5: 39 | J5: Clothing | K5: 4330.03 | L5: 4467.75 | M5: New | N5: 0.02 | O5: Credit Card | P5: Online | Q5: Delivered
A6: ORD1004 | B6: 1061 | C6: 45009 | D6: Rohit Gupta | E6: 47 | F6: Chennai | G6: Tamil Nadu | H6: South | I6: 13 | J6: Electronics | K6: 637.37 | L6: 692.71 | M6: New | N6: 0.08 | O6: Credit Card | P6: Online | Q6: Returned
A7: ORD1005 | B7: 1021 | C7: 44968 | D7: Abhishek Ghosh | E7: 59 | F7: Chennai | G7: Delhi | H7: North | I7: 32 | J7: Food | K7: 900.79 | L7: 1106.51 | M7: New | N7: 0.21 | O7: Cash | P7: Online | Q7: Returned
A8: ORD1006 | B8: 1083 | C8: 45027 | D8: Sneha Das | E8: 34 | F8: Bangalore | G8: Maharashtra | H8: South | I8: 29 | J8: Furniture | K8: 2408.81 | L8: 2824.09 | M8: Returning | N8: 0.04 | O8: Cash | P8: Offline | Q8: Cancelled
A9: ORD1007 | B9: 1087 | C9: 44932 | D9: Amit Malhotra | E9: 22 | F9: Bangalore | G9: Maharashtra | H9: East | I9: 46 | J9: Furniture | K9: 3702.51 | L9: 3964.65 | M9: New | N9: 0.12 | O9: Bank Transfer | P9: Offline | Q9: Returned
A10: ORD1008 | B10: 1075 | C10: 45106 | D10: Suman Das | E10: 46 | F10: Chennai | G10: Maharashtra | H10: North | I10: 30 | J10: Furniture | K10: 738.06 | L10: 1095.45 | M10: New | N10: 0.05 | O10: Bank Transfer | P10: Offline | Q10: Cancelled
A11: ORD1009 | B11: 1075 | C11: 45208 | D11: Kavita Ghosh | E11: 21 | F11: Delhi | G11: Tamil Nadu | H11: East | I11: 18 | J11: Clothing | K11: 2228.35 | L11: 2682.34 | M11: New | N11: 0.13 | O11: Bank Transfer | P11: Offline | Q11: Delivered
A12: ORD1010 | B12: 1088 | C12: 45246 | D12: Sourav Gupta | E12: 27 | F12: Mumbai | G12: Karnataka | H12: South | I12: 13 | J12: Furniture | K12: 2440.11 | L12: 2517.6 | M12: New | N12: 0.12 | O12: Bank Transfer | P12: Online | Q12: Returned
A13: ORD1011 | B13: 1100 | C13: 45152 | D13: Arjun Chatterjee | E13: 34 | F13: Mumbai | G13: Maharashtra | H13: West | I13: 43 | J13: Food | K13: 1100.81 | L13: 1137.44 | M13: Returning | N13: 0.08 | O13: Bank Transfer | P13: Online | Q13: Delivered
... A301: ORD1299 | B301: 1048 | C301: 44945 | D301: Arjun Iyer | E301: 30 | F301: Chennai | G301: West Bengal | H301: West | I301: 7 | J301: Clothing | K301: 4310.95 | L301: 4723.2 | M301: Returning | N301: 0.05 | O301: Credit Card | P301: Offline | Q301: Delivered

Sheet Functions
A1: Sales Analysis | I1: Customer Behaviour Analysis
A2: Sum,Sumif,Sumifs
A3: Q1. What is the total sales amount by region? | J3: Q1. Which customer type contributes more to sales?
B5: Region | C5: Total Sale Amount | K5: Customer_Type | L5: Sale_Amount
B6: East | C6: =SUMIF('Cleaned data'!I2:I301,Functions!B6,'Cleaned data'!S2:S301) -> 6273772.1 | K6: New | L6: =SUMIF('Cleaned data'!N2:N301,Functions!K6,'Cleaned data'!S2:S301) -> 9059644.3
B7: West | C7: =SUMIF('Cleaned data'!I3:I302,Functions!B7,'Cleaned data'!S3:S302) -> 4663455.6 | K7: Returning | L7: =SUMIF('Cleaned data'!N3:N302,Functions!K7,'Cleaned data'!S3:S302) -> 10697895
B8: north | C8: =SUMIF('Cleaned data'!I4:I303,Functions!B8,'Cleaned data'!S4:S303) -> 4613541.8
B9: South | C9: =SUMIF('Cleaned data'!I5:I304,Functions!B9,'Cleaned data'!S5:S304) -> 4211146.7 | J9: Q2.Which age group spends the most?
K11: Age_group | L11: Sale_Amount
A12: Q2. Which product category generates the highest revenue? | K12: Senior | L12: =SUMIF('Cleaned data'!V2:V301,Functions!K12,'Cleaned data'!S2:S301) -> 9815585
K13: Adult | L13: =SUMIF('Cleaned data'!V3:V302,Functions!K13,'Cleaned data'!S3:S302) -> 6554553.7
B14: Product_Category | C14: Hightst_profit | K14: Young | L14: =SUMIF('Cleaned data'!V4:V303,Functions!K14,'Cleaned data'!S4:S303) -> 3391777.5
B15: Furniture | C15: =SUMIF('Cleaned data'!K5:K304,Functions!B18,'Cleaned data'!U5:U304) -> -13088.395
B16: Food | C16: =SUMIF('Cleaned data'!K4:K303,Functions!B17,'Cleaned data'!U4:U303) -> -114312.43 | J16: Q3.Which payment method is most preferred by customers?
B17: Electronics | C17: =SUMIF('Cleaned data'!K3:K302,Functions!B16,'Cleaned data'!U3:U302) -> 62494.34
B18: Clothing | C18: =SUMIF('Cleaned data'!K2:K301,Functions!B15,'Cleaned data'!U2:U301) -> 96472.606 | K18: Payment_Method | L18: No. of Customer
K19: Bank Transfer | L19: =COUNTIF('Cleaned data'!P2:P301,K19) -> 108
A20: Q3. What is the total sales from delivered orders only? | K20: Cash | L20: =COUNTIF('Cleaned data'!P3:P302,K20) -> 86
K21: Credit Card | L21: =COUNTIF('Cleaned data'!P4:P303,K21) -> 105
B22: Order_Status | C22: Sale_Amount
B23: Delhivered | C23: =SUMIFS('Cleaned data'!S2:S301,'Cleaned data'!R2:R301,"Delivered") -> 6587419.8 | J23: Q4.Which sales channel do customers prefer?
A25: Q4. How does sales performance differ by sales channel? | K25: Sale_Channel | L25: Sale_Amount | M25: No. of Customer
K26: Online | L26: =SUMIF('Cleaned data'!Q2:Q301,Functions!K26,'Cleaned data'!S2:S301) -> 10677405 | M26: =COUNTIF('Cleaned data'!Q2:Q301,K26) -> 153
B27: Sale_Channel | C27: Sale_Amount | K27: Offline | L27: =SUMIF('Cleaned data'!Q3:Q302,Functions!K27,'Cleaned data'!S3:S302) -> 9080134.1 | M27: =COUNTIF('Cleaned data'!Q3:Q302,K27) -> 146
B28: Online | C28: =SUMIF('Cleaned data'!Q2:Q301,Functions!B28,'Cleaned data'!S2:S301) -> 10677405
B29: Offline | C29: =SUMIF('Cleaned data'!Q3:Q302,Functions!B29,'Cleaned data'!S3:S302) -> 9080134.1
A32: Logical If Functions,Nested if functions
A34: Q1. Can high-value orders be identified using sales and profit?
A35: Q2. Which orders are risky based on high discount or low quantity?
A36: Q3: Is the order delivered or not?
A37: Q4.How can quantity-based order size be identified?
A41: Order_ID | B41: Order_Value | C41: Order risky or not | D41: Order_delhivary_Status | E41: Order_Size
A42: ORD1000 | B42: =IF(AND('Cleaned data'!S2>2000,'Cleaned data'!U2>0),"High Value","Normal") -> High Value | C42: =IF(OR('Cleaned data'!O2>0.3,'Cleaned data'!J2<2),"Risky","Safe") -> Safe | D42: =IF('Cleaned data'!R2="Delivered","Completed","Not Completed") -> Completed | E42: =IF('Cleaned data'!J2>=15,"Bulk Order", IF('Cleaned data'!J2>=5,"Normal Order", "Small Order")) -> Bulk Order
A43: ORD1001 | B43: =IF(AND('Cleaned data'!S3>2000,'Cleaned data'!U3>0),"High Value","Normal") -> Normal | C43: =IF(OR('Cleaned data'!O3>0.3,'Cleaned data'!J3<2),"Risky","Safe") -> Safe | D43: =IF('Cleaned data'!R3="Delivered","Completed","Not Completed") -> Not Completed | E43: =IF('Cleaned data'!J3>=15,"Bulk Order", IF('Cleaned data'!J3>=5,"Normal Order", "Small Order")) -> Bulk Order
A44: ORD1002 | B44: =IF(AND('Cleaned data'!S4>2000,'Cleaned data'!U4>0),"High Value","Normal") -> High Value | C44: =IF(OR('Cleaned data'!O4>0.3,'Cleaned data'!J4<2),"Risky","Safe") -> Safe | D44: =IF('Cleaned data'!R4="Delivered","Completed","Not Completed") -> Not Completed | E44: =IF('Cleaned data'!J4>=15,"Bulk Order", IF('Cleaned data'!J4>=5,"Normal Order", "Small Order")) -> Bulk Order
A45: ORD1003 | B45: =IF(AND('Cleaned data'!S5>2000,'Cleaned data'!U5>0),"High Value","Normal") -> High Value | C45: =IF(OR('Cleaned data'!O5>0.3,'Cleaned data'!J5<2),"Risky","Safe") -> Safe | D45: =IF('Cleaned data'!R5="Delivered","Completed","Not Completed") -> Completed | E45: =IF('Cleaned data'!J5>=15,"Bulk Order", IF('Cleaned data'!J5>=5,"Normal Order", "Small Order")) -> Bulk Order
A46: ORD1004 | B46: =IF(AND('Cleaned data'!S6>2000,'Cleaned data'!U6>0),"High Value","Normal") -> Normal | C46: =IF(OR('Cleaned data'!O6>0.3,'Cleaned data'!J6<2),"Risky","Safe") -> Safe | D46: =IF('Cleaned data'!R6="Delivered","Completed","Not Completed") -> Not Completed | E46: =IF('Cleaned data'!J6>=15,"Bulk Order", IF('Cleaned data'!J6>=5,"Normal Order", "Small Order")) -> Normal Order
A47: ORD1005 | B47: =IF(AND('Cleaned data'!S7>2000,'Cleaned data'!U7>0),"High Value","Normal") -> Normal | C47: =IF(OR('Cleaned data'!O7>0.3,'Cleaned data'!J7<2),"Risky","Safe") -> Safe | D47: =IF('Cleaned data'!R7="Delivered","Completed","Not Completed") -> Not Completed | E47: =IF('Cleaned data'!J7>=15,"Bulk Order", IF('Cleaned data'!J7>=5,"Normal Order", "Small Order")) -> Bulk Order
A48: ORD1006 | B48: =IF(AND('Cleaned data'!S8>2000,'Cleaned data'!U8>0),"High Value","Normal") -> High Value | C48: =IF(OR('Cleaned data'!O8>0.3,'Cleaned data'!J8<2),"Risky","Safe") -> Safe | D48: =IF('Cleaned data'!R8="Delivered","Completed","Not Completed") -> Not Completed | E48: =IF('Cleaned data'!J8>=15,"Bulk Order", IF('Cleaned data'!J8>=5,"Normal Order", "Small Order")) -> Bulk Order
A49: ORD1007 | B49: =IF(AND('Cleaned data'!S9>2000,'Cleaned data'!U9>0),"High Value","Normal") -> Normal | C49: =IF(OR('Cleaned data'!O9>0.3,'Cleaned data'!J9<2),"Risky","Safe") -> Safe | D49: =IF('Cleaned data'!R9="Delivered","Completed","Not Completed") -> Not Completed | E49: =IF('Cleaned data'!J9>=15,"Bulk Order", IF('Cleaned data'!J9>=5,"Normal Order", "Small Order")) -> Bulk Order
...

Sheet Sort n filter
A1: 1.Profit making online delivered orders highest to lowest amount of sale
A3: Order_ID | B3: Quantity_Sold | C3: Product_Category | D3: Unit_Cost | E3: Unit_Price | F3: Customer_Type | G3: Discount | H3: Payment_Method | I3: Sales_Channel | J3: Order_Status | K3: Sales_Amount | L3: Cost_Price | M3: Profit
A4: ORD1188 | B4: 47 | C4: Food | D4: 4284.98 | E4: 5862.4 | F4: New | G4: 0.28 | H4: Credit Card | I4: Offline | J4: Delivered | K4: =B4*E4*(1-G4) -> 198383.62 | L4: =D4*B4 -> 201394.06 | M4: =K4-L4 -> -3010.444
A5: ORD1001 | B5: 17 | C5: Furniture | D5: 3816.39 | E5: 4209.44 | F5: Returning | G5: 0.1 | H5: Cash | I5: Online | J5: Cancelled | K5: =B5*E5*(1-G5) -> 64404.432 | L5: =D5*B5 -> 64878.63 | M5: =K5-L5 -> -474.198
A6: ORD1002 | B6: 30 | C6: Food | D6: 261.56 | E6: 371.4 | F6: Returning | G6: 0.2 | H6: Bank Transfer | I6: Online | J6: Returned | K6: =B6*E6*(1-G6) -> 8913.6 | L6: =D6*B6 -> 7846.8 | M6: =K6-L6 -> 1066.8
A7: ORD1040 | B7: 45 | C7: Furniture | D7: 4849.6 | E7: 5166.72 | F7: Returning | G7: 0.15 | H7: Credit Card | I7: Online | J7: Delivered | K7: =B7*E7*(1-G7) -> 197627.04 | L7: =D7*B7 -> 218232 | M7: =K7-L7 -> -20604.96
A8: ORD1004 | B8: 13 | C8: Electronics | D8: 637.37 | E8: 692.71 | F8: New | G8: 0.08 | H8: Credit Card | I8: Online | J8: Returned | K8: =B8*E8*(1-G8) -> 8284.8116 | L8: =D8*B8 -> 8285.81 | M8: =K8-L8 -> -0.9984
A9: ORD1005 | B9: 32 | C9: Food | D9: 900.79 | E9: 1106.51 | F9: New | G9: 0.21 | H9: Cash | I9: Online | J9: Returned | K9: =B9*E9*(1-G9) -> 27972.573 | L9: =D9*B9 -> 28825.28 | M9: =K9-L9 -> -852.7072
A10: ORD1006 | B10: 29 | C10: Furniture | D10: 2408.81 | E10: 2824.09 | F10: Returning | G10: 0.04 | H10: Cash | I10: Offline | J10: Cancelled | K10: =B10*E10*(1-G10) -> 78622.666 | L10: =D10*B10 -> 69855.49 | M10: =K10-L10 -> 8767.1756
A11: ORD1007 | B11: 46 | C11: Furniture | D11: 3702.51 | E11: 3964.65 | F11: New | G11: 0.12 | H11: Bank Transfer | I11: Offline | J11: Returned | K11: =B11*E11*(1-G11) -> 160489.03 | L11: =D11*B11 -> 170315.46 | M11: =K11-L11 -> -9826.428
A12: ORD1008 | B12: 30 | C12: Furniture | D12: 738.06 | E12: 1095.45 | F12: New | G12: 0.05 | H12: Bank Transfer | I12: Offline | J12: Cancelled | K12: =B12*E12*(1-G12) -> 31220.325 | L12: =D12*B12 -> 22141.8 | M12: =K12-L12 -> 9078.525
A13: ORD1126 | B13: 45 | C13: Clothing | D13: 4369.5 | E13: 4381.89 | F13: Returning | G13: 0.02 | H13: Credit Card | I13: Online | J13: Delivered | K13: =B13*E13*(1-G13) -> 193241.35 | L13: =D13*B13 -> 196627.5 | M13: =K13-L13 -> -3386.151
A14: ORD1010 | B14: 13 | C14: Furniture | D14: 2440.11 | E14: 2517.6 | F14: New | G14: 0.12 | H14: Bank Transfer | I14: Online | J14: Returned | K14: =B14*E14*(1-G14) -> 28801.344 | L14: =D14*B14 -> 31721.43 | M14: =K14-L14 -> -2920.086
A15: ORD1144 | B15: 49 | C15: Furniture | D15: 3026.85 | E15: 5183.58 | F15: Returning | G15: 0.25 | H15: Cash | I15: Online | J15: Delivered | K15: =B15*E15*(1-G15) -> 190496.57 | L15: =D15*B15 -> 148315.65 | M15: =K15-L15 -> 42180.915
... A303: ORD1162 | B303: 1 | C303: Food | D303: 182.99 | E303: 211.18 | F303: Returning | G303: 0.27 | H303: Bank Transfer | I303: Offline | J303: Delivered | K303: =B303*E303*(1-G303) -> 154.1614 | L303: =D303*B303 -> 182.99 | M303: =K303-L303 -> -28.8286

Sheet Conditional Formating
A1: Order_ID | B1: Sale_Date | C1: Month | D1: State | E1: Quantity_Sold | F1: Product_Category | G1: Unit_Cost | H1: Unit_Price | I1: Customer_Type | J1: Discount | K1: Payment_Method | L1: Sales_Channel | M1: Order_Status | N1: Sales_Amount | O1: Cost_Price | P1: Profit
A2: ORD1000 | B2: 44960 | C2: =TEXT(B2,"mmm") -> Feb | D2: Karnataka | E2: 18 | F2: Furniture | G2: 152.75 | H2: 267.22 | I2: Returning | J2: 0.09 | K2: Cash | L2: Offline | M2: Delivered | N2: =E2*H2*(1-J2) -> 4377.0636 | O2: =G2*E2 -> 2749.5 | P2: =N2-O2 -> 1627.5636 | R2: 1.Top 10% Sale amountin green fill
A3: ORD1001 | B3: 45037 | C3: =TEXT(B3,"mmm") -> Apr | D3: Tamil Nadu | E3: 17 | F3: Furniture | G3: 3816.39 | H3: 4209.44 | I3: Returning | J3: 0.1 | K3: Cash | L3: Online | M3: Cancelled | N3: =E3*H3*(1-J3) -> 64404.432 | O3: =G3*E3 -> 64878.63 | P3: =N3-O3 -> -474.198 | R3: 2.Highlight with light yellow entire rows where order is Delhivered
A4: ORD1002 | B4: 45190 | C4: =TEXT(B4,"mmm") -> Sep | D4: Maharashtra | E4: 30 | F4: Food | G4: 261.56 | H4: 371.4 | I4: Returning | J4: 0.2 | K4: Bank Transfer | L4: Online | M4: Returned | N4: =E4*H4*(1-J4) -> 8913.6 | O4: =G4*E4 -> 7846.8 | P4: =N4-O4 -> 1066.8 | R4: 3.Highlight with red very high discounts
A5: ORD1003 | B5: 45162 | C5: =TEXT(B5,"mmm") -> Aug | D5: Tamil Nadu | E5: 39 | F5: Clothing | G5: 4330.03 | H5: 4467.75 | I5: New | J5: 0.02 | K5: Credit Card | L5: Online | M5: Delivered | N5: =E5*H5*(1-J5) -> 170757.4 | O5: =G5*E5 -> 168871.17 | P5: =N5-O5 -> 1886.235 | R5: 4.Top 10% profit highlight with grey
A6: ORD1004 | B6: 45009 | C6: =TEXT(B6,"mmm") -> Mar | D6: Tamil Nadu | E6: 13 | F6: Electronics | G6: 637.37 | H6: 692.71 | I6: New | J6: 0.08 | K6: Credit Card | L6: Online | M6: Returned | N6: =E6*H6*(1-J6) -> 8284.8116 | O6: =G6*E6 -> 8285.81 | P6: =N6-O6 -> -0.9984
A7: ORD1005 | B7: 44968 | C7: =TEXT(B7,"mmm") -> Feb | D7: Delhi | E7: 32 | F7: Food | G7: 900.79 | H7: 1106.51 | I7: New | J7: 0.21 | K7: Cash | L7: Online | M7: Returned | N7: =E7*H7*(1-J7) -> 27972.573 | O7: =G7*E7 -> 28825.28 | P7: =N7-O7 -> -852.7072
A8: ORD1006 | B8: 45027 | C8: =TEXT(B8,"mmm") -> Apr | D8: Maharashtra | E8: 29 | F8: Furniture | G8: 2408.81 | H8: 2824.09 | I8: Returning | J8: 0.04 | K8: Cash | L8: Offline | M8: Cancelled | N8: =E8*H8*(1-J8) -> 78622.666 | O8: =G8*E8 -> 69855.49 | P8: =N8-O8 -> 8767.1756
A9: ORD1007 | B9: 44932 | C9: =TEXT(B9,"mmm") -> Jan | D9: Maharashtra | E9: 46 | F9: Furniture | G9: 3702.51 | H9: 3964.65 | I9: New | J9: 0.12 | K9: Bank Transfer | L9: Offline | M9: Returned | N9: =E9*H9*(1-J9) -> 160489.03 | O9: =G9*E9 -> 170315.46 | P9: =N9-O9 -> -9826.428
A10: ORD1008 | B10: 45106 | C10: =TEXT(B10,"mmm") -> Jun | D10: Maharashtra | E10: 30 | F10: Furniture | G10: 738.06 | H10: 1095.45 | I10: New | J10: 0.05 | K10: Bank Transfer | L10: Offline | M10: Cancelled | N10: =E10*H10*(1-J10) -> 31220.325 | O10: =G10*E10 -> 22141.8 | P10: =N10-O10 -> 9078.525
A11: ORD1009 | B11: 45208 | C11: =TEXT(B11,"mmm") -> Oct | D11: Tamil Nadu | E11: 18 | F11: Clothing | G11: 2228.35 | H11: 2682.34 | I11: New | J11: 0.13 | K11: Bank Transfer | L11: Offline | M11: Delivered | N11: =E11*H11*(1-J11) -> 42005.444 | O11: =G11*E11 -> 40110.3 | P11: =N11-O11 -> 1895.1444
A12: ORD1010 | B12: 45246 | C12: =TEXT(B12,"mmm") -> Nov | D12: Karnataka | E12: 13 | F12: Furniture | G12: 2440.11 | H12: 2517.6 | I12: New | J12: 0.12 | K12: Bank Transfer | L12: Online | M12: Returned | N12: =E12*H12*(1-J12) -> 28801.344 | O12: =G12*E12 -> 31721.43 | P12: =N12-O12 -> -2920.086
A13: ORD1011 | B13: 45152 | C13: =TEXT(B13,"mmm") -> Aug | D13: Maharashtra | E13: 43 | F13: Food | G13: 1100.81 | H13: 1137.44 | I13: Returning | J13: 0.08 | K13: Bank Transfer | L13: Online | M13: Delivered | N13: =E13*H13*(1-J13) -> 44997.126 | O13: =G13*E13 -> 47334.83 | P13: =N13-O13 -> -2337.7036
A14: ORD1012 | B14: 45241 | C14: =TEXT(B14,"mmm") -> Nov | D14: Tamil Nadu | E14: 21 | F14: Food | G14: 622.01 | H14: 641.09 | I14: Returning | J14: 0 | K14: Bank Transfer | L14: Online | M14: Returned | N14: =E14*H14*(1-J14) -> 13462.89 | O14: =G14*E14 -> 13062.21 | P14: =N14-O14 -> 400.68
A15: ORD1013 | B15: 45291 | C15: =TEXT(B15,"mmm") -> Dec | D15: Delhi | E15: 30 | F15: Furniture | G15: 4190.28 | H15: 4270.65 | I15: New | J15: 0.06 | K15: Cash | L15: Online | M15: Delivered | N15: =E15*H15*(1-J15) -> 120432.33 | O15: =G15*E15 -> 125708.4 | P15: =N15-O15 -> -5276.07
A16: ORD1014 | B16: 45155 | C16: =TEXT(B16,"mmm") -> Aug | D16: Karnataka | E16: 21 | F16: Food | G16: 2537.2 | H16: 2869.6 | I16: New | J16: 0.2 | K16: Bank Transfer | L16: Online | M16: Returned | N16: =E16*H16*(1-J16) -> 48209.28 | O16: =G16*E16 -> 53281.2 | P16: =N16-O16 -> -5071.92
A17: ORD1015 | B17: 45215 | C17: =TEXT(B17,"mmm") -> Oct | D17: Delhi | E17: 48 | F17: Furniture | G17: 121.19 | H17: 487.65 | I17: New | J17: 0.18 | K17: Cash | L17: Offline | M17: Returned | N17: =E17*H17*(1-J17) -> 19193.904 | O17: =G17*E17 -> 5817.12 | P17: =N17-O17 -> 13376.784
... A301: ORD1299 | B301: 44945 | C301: =TEXT(B301,"mmm") -> Jan | D301: West Bengal | E301: 7 | F301: Clothing | G301: 4310.95 | H301: 4723.2 | I301: Returning | J301: 0.05 | K301: Credit Card | L301: Offline | M301: Delivered | N301: =E301*H301*(1-J301) -> 31409.28 | O301: =G301*E301 -> 30176.65 | P301: =N301-O301 -> 1232.63

Sheet lookups and indexmatch
A1: VLOOKUP | K1: Index match
A3: Q1.Find Unit Price using Product_ID | F3: Q2.Get Customer Type from Order_ID | K3: Q1.Find Customer Name from Order_ID
F4: Q3.Find Sales_Channel using Order_ID | K4: Q2.Get Discount Applied on an Order
A5: Product_ID | B5: Unit Price
A6: 1052 | B6: =VLOOKUP('Cleaned data'!B2:B301,'Cleaned data'!B1:V301,12,0) -> 692.71 | F6: Order_ID | G6: Customer_Type | H6: Sale_Channel | K6: Order_ID | L6: Customer_Name | M6: Discount
A7: 1093 | B7: =VLOOKUP('Cleaned data'!B3:B302,'Cleaned data'!B2:V302,12,0) -> 1106.51 | F7: ORD1000 | G7: =VLOOKUP('Cleaned data'!$A$2:$A$301,'Cleaned data'!$A$1:$V$301,14,0) -> New | H7: =VLOOKUP('Cleaned data'!A2:A301,'Cleaned data'!A1:V301,17,0) -> Online | K7: ORD1062 | L7: =INDEX('Cleaned data'!E1:E301,MATCH(K7,'Cleaned data'!A1:A301,0)) -> Anita Iyer | M7: =INDEX('Cleaned data'!O1:O301,MATCH(K7,'Cleaned data'!A1:A301,0)) -> 0.06
A8: 1015 | B8: =VLOOKUP('Cleaned data'!B4:B303,'Cleaned data'!B3:V303,12,0) -> 2824.09 | F8: ORD1001 | G8: =VLOOKUP('Cleaned data'!$A$2:$A$301,'Cleaned data'!$A$1:$V$301,14,0) -> Returning | H8: =VLOOKUP('Cleaned data'!A3:A302,'Cleaned data'!A2:V302,17,0) -> Offline
A9: 1072 | B9: =VLOOKUP('Cleaned data'!B5:B304,'Cleaned data'!B4:V304,12,0) -> 3964.65 | F9: ORD1002 | G9: =VLOOKUP('Cleaned data'!$A$2:$A$301,'Cleaned data'!$A$1:$V$301,14,0) -> New | H9: =VLOOKUP('Cleaned data'!A4:A303,'Cleaned data'!A3:V303,17,0) -> Offline
A10: 1061 | B10: =VLOOKUP('Cleaned data'!B6:B305,'Cleaned data'!B5:V305,12,0) -> 1095.45 | F10: ORD1003 | G10: =VLOOKUP('Cleaned data'!$A$2:$A$301,'Cleaned data'!$A$1:$V$301,14,0) -> New | H10: =VLOOKUP('Cleaned data'!A5:A304,'Cleaned data'!A4:V304,17,0) -> Offline
A11: 1021 | B11: =VLOOKUP('Cleaned data'!B7:B306,'Cleaned data'!B6:V306,12,0) -> 1095.45 | F11: ORD1004 | G11: =VLOOKUP('Cleaned data'!$A$2:$A$301,'Cleaned data'!$A$1:$V$301,14,0) -> New | H11: =VLOOKUP('Cleaned data'!A6:A305,'Cleaned data'!A5:V305,17,0) -> Offline
A12: 1083 | B12: =VLOOKUP('Cleaned data'!B8:B307,'Cleaned data'!B7:V307,12,0) -> 2517.6 | F12: ORD1005 | G12: =VLOOKUP('Cleaned data'!$A$2:$A$301,'Cleaned data'!$A$1:$V$301,14,0) -> New | H12: =VLOOKUP('Cleaned data'!A7:A306,'Cleaned data'!A6:V306,17,0) -> Online
A13: 1087 | B13: =VLOOKUP('Cleaned data'!B9:B308,'Cleaned data'!B8:V308,12,0) -> 1137.44 | F13: ORD1006+FF13:H296 | G13: =VLOOKUP('Cleaned data'!$A$2:$A$301,'Cleaned data'!$A$1:$V$301,14,0) -> Returning | H13: =VLOOKUP('Cleaned data'!A8:A307,'Cleaned data'!A7:V307,17,0) -> Online
A14: 1075 | B14: =VLOOKUP('Cleaned data'!B10:B309,'Cleaned data'!B9:V309,12,0) -> 641.09 | F14: ORD1007 | G14: =VLOOKUP('Cleaned data'!$A$2:$A$301,'Cleaned data'!$A$1:$V$301,14,0) -> Returning | H14: =VLOOKUP('Cleaned data'!A9:A308,'Cleaned data'!A8:V308,17,0) -> Online
A15: 1088 | B15: =VLOOKUP('Cleaned data'!B11:B310,'Cleaned data'!B10:V310,12,0) -> 4270.65 | F15: ORD1008 | G15: =VLOOKUP('Cleaned data'!$A$2:$A$301,'Cleaned data'!$A$1:$V$301,14,0) -> New | H15: =VLOOKUP('Cleaned data'!A10:A309,'Cleaned data'!A9:V309,17,0) -> Online
A16: 1100 | B16: =VLOOKUP('Cleaned data'!B12:B311,'Cleaned data'!B11:V311,12,0) -> 2869.6 | F16: ORD1009 | G16: =VLOOKUP('Cleaned data'!$A$2:$A$301,'Cleaned data'!$A$1:$V$301,14,0) -> New | H16: =VLOOKUP('Cleaned data'!A11:A310,'Cleaned data'!A10:V310,17,0) -> Online
A17: 1024 | B17: =VLOOKUP('Cleaned data'!B13:B312,'Cleaned data'!B12:V312,12,0) -> 487.65 | F17: ORD1010 | G17: =VLOOKUP('Cleaned data'!$A$2:$A$301,'Cleaned data'!$A$1:$V$301,14,0) -> New | H17: =VLOOKUP('Cleaned data'!A12:A311,'Cleaned data'!A11:V311,17,0) -> Offline
A18: 1003 | B18: =VLOOKUP('Cleaned data'!B14:B313,'Cleaned data'!B13:V313,12,0) -> 4420.15 | F18: ORD1011 | G18: =VLOOKUP('Cleaned data'!$A$2:$A$301,'Cleaned data'!$A$1:$V$301,14,0) -> Returning | H18: =VLOOKUP('Cleaned data'!A13:A312,'Cleaned data'!A12:V312,17,0) -> Offline
A19: 1022 | B19: =VLOOKUP('Cleaned data'!B15:B314,'Cleaned data'!B14:V314,12,0) -> 5034.35 | F19: ORD1012 | G19: =VLOOKUP('Cleaned data'!$A$2:$A$301,'Cleaned data'!$A$1:$V$301,14,0) -> New | H19: =VLOOKUP('Cleaned data'!A14:A313,'Cleaned data'!A13:V313,17,0) -> Online
... A45: 1014 | B45: =VLOOKUP('Cleaned data'!B41:B340,'Cleaned data'!B40:V340,12,0) -> 4417.79 | F45: ORD1038 | G45: =VLOOKUP('Cleaned data'!$A$2:$A$301,'Cleaned data'!$A$1:$V$301,14,0) -> Returning | H45: =VLOOKUP('Cleaned data'!A40:A339,'Cleaned data'!A39:V339,17,0) -> Online
A46: 1009 | B46: =VLOOKUP('Cleaned data'!B42:B341,'Cleaned data'!B41:V341,12,0) -> 853.66
A47: 1090 | B47: =VLOOKUP('Cleaned data'!B43:B342,'Cleaned data'!B42:V342,12,0) -> 3710.92
A48: 1084 | B48: =VLOOKUP('Cleaned data'!B44:B343,'Cleaned data'!B43:V343,12,0) -> 2637.91
A49: 1071 | B49: =VLOOKUP('Cleaned data'!B45:B344,'Cleaned data'!B44:V344,12,0) -> 4469.07
A50: 1044 | B50: =VLOOKUP('Cleaned data'!B46:B345,'Cleaned data'!B45:V345,12,0) -> 3007.47
A51: 1008 | B51: =VLOOKUP('Cleaned data'!B47:B346,'Cleaned data'!B46:V346,12,0) -> 3600.14
A52: 1035 | B52: =VLOOKUP('Cleaned data'!B48:B347,'Cleaned data'!B47:V347,12,0) -> 2519.07
A53: 1078 | B53: =VLOOKUP('Cleaned data'!B49:B348,'Cleaned data'!B48:V348,12,0) -> 2778.4
A54: 1081 | B54: =VLOOKUP('Cleaned data'!B50:B349,'Cleaned data'!B49:V349,12,0) -> 4186.98
A55: 1036 | B55: =VLOOKUP('Cleaned data'!B51:B350,'Cleaned data'!B50:V350,12,0) -> 3339.66
A56: 1050 | B56: =VLOOKUP('Cleaned data'!B52:B351,'Cleaned data'!B51:V351,12,0) -> 3204.01
A57: 1006 | B57: =VLOOKUP('Cleaned data'!B53:B352,'Cleaned data'!B52:V352,12,0) -> 2626.9
... A102: 1031 | B102: =VLOOKUP('Cleaned data'!B98:B397,'Cleaned data'!B97:V397,12,0) -> 1715.83

Sheet Pivot Tables
A3: Q1: How does total sales vary across regions? | F3: Q4.Which states have high revenue but low number of orders?
A5: Row Labels | B5: Sum of Sales_Amount | H5: Row Labels | I5: Count of Order_ID | J5: Sum of Sales_Amount
A6: East | B6: 6273772.1 | H6: Delhi | I6: 46 | J6: 3250546
A7: North | B7: 4613541.8 | H7: Karnataka | I7: 74 | J7: 5497247.1
A8: South | B8: 4211146.7 | H8: Maharashtra | I8: 63 | J8: 3681359.9
A9: West | B9: 4663455.6 | H9: Tamil Nadu | I9: 48 | J9: 2951538.3
A10: Grand Total | B10: 19761916 | H10: West Bengal | I10: 69 | J10: 4381224.9
H11: Grand Total | I11: 300 | J11: 19761916
A14: Q2.What are the top 2 product categories by revenue? | H14: Q5.What proportion of orders are cancelled or not delivered?
A16: Row Labels | B16: Sum of Sales_Amount | H16: Row Labels | I16: Count of Order_ID
A17: Clothing | B17: 5804098.2 | H17: Cancelled | I17: 98
A18: Furniture | B18: 5482977.4 | H18: Delivered | I18: 106
A19: Grand Total | B19: 11287076 | H19: Returned | I19: 96
H20: Grand Total | I20: 300
A21: Q3.Who are the top 10 customers by total sales amount?
G22: Q6. Which product category dominates sales within each region?
A23: Row Labels | B23: Sum of Sales_Amount
A24: Abhishek Patel | B24: 442753.67 | G24: Sum of Sales_Amount | H24: Column Labels
A25: Anita Patel | B25: 421484.83 | G25: Row Labels | H25: Furniture | I25: Food | J25: Electronics | K25: Clothing
A26: Anita Singh | B26: 332329.3 | G26: East | H26: 1737450.5 | I26: 1113771.2 | J26: 1079150.3 | K26: 2343400.1
A27: Anjali Chatterjee | B27: 499807.66 | G27: North | H27: 1308788.1 | I27: 1056136.6 | J27: 848549.94 | K27: 1400067.2
A28: Priya Gupta | B28: 358881.01 | G28: South | H28: 900425.77 | I28: 996369.9 | J28: 1227796.9 | K28: 1086554.2
A29: Priya Mukherjee | B29: 340588.88 | G29: West | H29: 1536313.1 | I29: 853213.33 | J29: 1299852.5 | K29: 974076.7
A30: Rahul Iyer | B30: 397991.95 | G30: Grand Total | H30: 5482977.4 | I30: 4019491 | J30: 4455349.6 | K30: 5804098.2
A31: Rahul Mukherjee | B31: 361840.17
A32: Sneha Gupta | B32: 495056.06
A33: Sourav Chatterjee | B33: 407783.44
A34: Grand Total | B34: 4058517

Sheet Visualization
A1: Retail Sale Dashboard

Sheet Pivot Table for pivot Chart 
H2: Row Labels | I2: Sum of Sales_Amount
A3: Row Labels | B3: Sum of Sales_Amount | C3: Count of Order_ID | E3: Row Labels | F3: Sum of Sales_Amount | H3: Cancelled | I3: 0.32788151
A4: Jan | B4: 1705440.4 | C4: 26 | E4: Adult | F4: 6554553.7 | H4: Offline | I4: 0.17406211
A5: Feb | B5: 1107629.7 | C5: 19 | E5: Senior | F5: 9815585 | H5: Online | I5: 0.15381941
A6: Mar | B6: 1473460.5 | C6: 23 | E6: Young | F6: 3391777.5 | H6: Delivered | I6: 0.33333912
A7: Apr | B7: 1845567.6 | C7: 28 | E7: Grand Total | F7: 19761916 | H7: Offline | I7: 0.1543671
A8: May | B8: 2253097.7 | C8: 30 | H8: Online | I8: 0.17897202
A9: Jun | B9: 2091856.5 | C9: 28 | H9: Returned | I9: 0.33877936
A10: Jul | B10: 1125588.2 | C10: 16 | E10: Row Labels | F10: Count of Order_ID | H10: Offline | I10: 0.13126868
A11: Aug | B11: 1472815.8 | C11: 21 | E11: Cancelled | F11: 98 | H11: Online | I11: 0.20751068
A12: Sep | B12: 1153110.6 | C12: 16 | E12: Delivered | F12: 106 | H12: Grand Total | I12: 1
A13: Oct | B13: 2276406.2 | C13: 32 | E13: Returned | F13: 96
A14: Nov | B14: 1457303.9 | C14: 37 | E14: Grand Total | F14: 300
A15: Dec | B15: 1799639.1 | C15: 24 | H15: Row Labels | I15: Count of Customer_Name
E16: Row Labels | F16: Sum of Sales_Amount | H16: Jan | I16: 26
E17: Delhi | F17: 3250546 | H17: Feb | I17: 19
E18: Karnataka | F18: 5497247.1 | H18: Mar | I18: 23
E19: Maharashtra | F19: 3681359.9 | H19: Apr | I19: 28
E20: Tamil Nadu | F20: 2951538.3 | H20: May | I20: 30
E21: West Bengal | F21: 4381224.9 | H21: Jun | I21: 28
H22: Jul | I22: 16
H23: Aug | I23: 21
H24: Sep | I24: 16
H25: Oct | I25: 32
A26: Sum of Profit | B26: Column Labels | H26: Nov | I26: 37
A27: Row Labels | B27: Clothing | C27: Electronics | D27: Food | E27: Furniture | H27: Dec | I27: 24
A28: Jan | B28: -16610.719 | C28: -35902.067 | D28: 20802.528 | E28: -22447.664 | H28: Grand Total | I28: 300
A29: Feb | B29: -374.489 | C29: 12170.902 | D29: 24969.75 | E29: 32021.213
A30: Mar | B30: 3784.3156 | C30: -1649.2507 | D30: 17250.37 | E30: -25175.469
A31: Apr | B31: 7485.1946 | C31: -17636.707 | D31: 10722.656 | E31: 12263.921
A32: May | B32: -29033.433 | C32: 3610.333 | D32: -14109.454 | E32: 56854.19
A33: Jun | B33: 15617.033 | C33: 29671.469 | D33: -20719.605 | E33: 25641.14
A34: Jul | B34: -13743.792 | C34: -17575.292 | D34: 16614.75 | E34: -430.7503
A35: Aug | B35: 16578.288 | C35: -3971.2899 | D35: 18.9366 | E35: 14104.796
A36: Sep | B36: -3650.637 | C36: -4866.9036 | D36: 6268.7131 | E36: -2519.7688
A37: Oct | B37: -3885.6437 | C37: -55162.579 | D37: -5249.3039 | E37: 4039.8488
A38: Nov | B38: -14237.729 | C38: 1586.2484 | D38: -35.2513 | E38: 23082.652
A39: Dec | B39: 24983.217 | C39: -24587.297 | D39: 5960.2513 | E39: -20961.503
